Workbook

Sheet Employee_Database
A1: Employee ID | B1: Full Name | C1: Gender | D1: Department | E1: Designation | F1: Joining Date | G1: Email | H1: Phone Number | I1: Salary | J1: Employment Status | M1: EMPLOYEE SEARCH | P1: Employee ID | Q1: Present Days | R1: Absent Days | S1: Leave Days | T1: Half Days | U1: Attendance
A2: EMP001 | B2: Rohan Mehta | C2: Male | D2: IT | E2: Software Engineer | F2: 44533 | G2: rohan.mehta@coffeecore.com | H2: 9876543210 | I2: 45000 | J2: Active | M2: Enter Employee ID: | N2: EMP011 | P2: {=tbl_Employee[Employee ID]} -> EMP001 | Q2: =COUNTIFS(Attendance!$B$2:$B$1201, P2, Attendance!$E$2:$E$1201, "Present") -> 26 | R2: =COUNTIFS(Attendance!$B$2:$B$1201, P2, Attendance!$E$2:$E$1201, "Absent") -> 4 | S2: =COUNTIFS(Attendance!$B$2:$B$1201, P2, Attendance!$E$2:$E$1201, "Leave") -> 0 | T2: =COUNTIFS(Attendance!$B$2:$B$1201, P2, Attendance!$E$2:$E$1201, "Half Day") -> 0 | U2: =ROUND((Q2 + T2*0.5) / (Q2+R2+S2+T2) * 100, 1) -> 86.7
A3: EMP002 | B3: Priya Sharma | C3: Female | D3: HR | E3: HR Executive | F3: 43958 | G3: priya.sharma@coffeecore.com | H3: 9876543211 | I3: 38000 | J3: Active | M3: Full Name | N3: =_xlfn.XLOOKUP($N$2, tbl_Employee[Employee ID], tbl_Employee[Full Name]) -> Arjun Desai | P3: EMP002 | Q3: =COUNTIFS(Attendance!$B$2:$B$1201, P3, Attendance!$E$2:$E$1201, "Present") -> 24 | R3: =COUNTIFS(Attendance!$B$2:$B$1201, P3, Attendance!$E$2:$E$1201, "Absent") -> 6 | S3: =COUNTIFS(Attendance!$B$2:$B$1201, P3, Attendance!$E$2:$E$1201, "Leave") -> 0 | T3: =COUNTIFS(Attendance!$B$2:$B$1201, P3, Attendance!$E$2:$E$1201, "Half Day") -> 0 | U3: =ROUND((Q3 + T3*0.5) / (Q3+R3+S3+T3) * 100, 1) -> 80
A4: EMP003 | B4: Aman Gupta | C4: Male | D4: Sales | E4: Sales Manager | F4: 18-01-2019 | G4: aman.gupta@coffeecore.com | H4: 9876543212 | I4: 55000 | J4: Active | M4: Gender | N4: =_xlfn.XLOOKUP($N$2, tbl_Employee[Employee ID], tbl_Employee[Gender]) -> Male | P4: EMP003 | Q4: =COUNTIFS(Attendance!$B$2:$B$1201, P4, Attendance!$E$2:$E$1201, "Present") -> 27 | R4: =COUNTIFS(Attendance!$B$2:$B$1201, P4, Attendance!$E$2:$E$1201, "Absent") -> 1 | S4: =COUNTIFS(Attendance!$B$2:$B$1201, P4, Attendance!$E$2:$E$1201, "Leave") -> 1 | T4: =COUNTIFS(Attendance!$B$2:$B$1201, P4, Attendance!$E$2:$E$1201, "Half Day") -> 1 | U4: =ROUND((Q4 + T4*0.5) / (Q4+R4+S4+T4) * 100, 1) -> 91.7
A5: EMP004 | B5: Sneha Verma | C5: Female | D5: Finance | E5: Accountant | F5: 22-09-2022 | G5: sneha.verma@coffeecore.com | H5: 9876543213 | I5: 42000 | J5: Active | M5: Department | N5: =_xlfn.XLOOKUP($N$2, tbl_Employee[Employee ID], tbl_Employee[Department]) -> IT | P5: EMP004 | Q5: =COUNTIFS(Attendance!$B$2:$B$1201, P5, Attendance!$E$2:$E$1201, "Present") -> 24 | R5: =COUNTIFS(Attendance!$B$2:$B$1201, P5, Attendance!$E$2:$E$1201, "Absent") -> 2 | S5: =COUNTIFS(Attendance!$B$2:$B$1201, P5, Attendance!$E$2:$E$1201, "Leave") -> 4 | T5: =COUNTIFS(Attendance!$B$2:$B$1201, P5, Attendance!$E$2:$E$1201, "Half Day") -> 0 | U5: =ROUND((Q5 + T5*0.5) / (Q5+R5+S5+T5) * 100, 1) -> 80
A6: EMP005 | B6: Vikram Singh | C6: Male | D6: Operations | E6: Operations Executive | F6: 44480 | G6: vikram.singh@coffeecore.com | H6: 9876543214 | I6: 36000 | J6: Active | M6: Designation | N6: =_xlfn.XLOOKUP($N$2, tbl_Employee[Employee ID], tbl_Employee[Designation]) -> Software Engineer | P6: EMP005 | Q6: =COUNTIFS(Attendance!$B$2:$B$1201, P6, Attendance!$E$2:$E$1201, "Present") -> 26 | R6: =COUNTIFS(Attendance!$B$2:$B$1201, P6, Attendance!$E$2:$E$1201, "Absent") -> 2 | S6: =COUNTIFS(Attendance!$B$2:$B$1201, P6, Attendance!$E$2:$E$1201, "Leave") -> 1 | T6: =COUNTIFS(Attendance!$B$2:$B$1201, P6, Attendance!$E$2:$E$1201, "Half Day") -> 1 | U6: =ROUND((Q6 + T6*0.5) / (Q6+R6+S6+T6) * 100, 1) -> 88.3
A7: EMP006 | B7: Anjali Nair | C7: Female | D7: IT | E7: IT Manager | F7: 43161 | G7: anjali.nair@coffeecore.com | H7: 9876543215 | I7: 62000 | J7: Active | M7: Joining Date | N7: =_xlfn.XLOOKUP($N$2, tbl_Employee[Employee ID], tbl_Employee[Joining Date]) -> 21-05-2022 | P7: EMP006 | Q7: =COUNTIFS(Attendance!$B$2:$B$1201, P7, Attendance!$E$2:$E$1201, "Present") -> 25 | R7: =COUNTIFS(Attendance!$B$2:$B$1201, P7, Attendance!$E$2:$E$1201, "Absent") -> 3 | S7: =COUNTIFS(Attendance!$B$2:$B$1201, P7, Attendance!$E$2:$E$1201, "Leave") -> 1 | T7: =COUNTIFS(Attendance!$B$2:$B$1201, P7, Attendance!$E$2:$E$1201, "Half Day") -> 1 | U7: =ROUND((Q7 + T7*0.5) / (Q7+R7+S7+T7) * 100, 1) -> 85
A8: EMP007 | B8: Karan Malhotra | C8: Male | D8: Sales | E8: Sales Executive | F8: 14-06-2023 | G8: karan.malhotra@coffeecore.com | H8: 9876543216 | I8: 32000 | J8: Active | M8: Email | N8: =_xlfn.XLOOKUP($N$2, tbl_Employee[Employee ID], tbl_Employee[Email]) -> arjun.desai@coffeecore.com | P8: EMP007 | Q8: =COUNTIFS(Attendance!$B$2:$B$1201, P8, Attendance!$E$2:$E$1201, "Present") -> 27 | R8: =COUNTIFS(Attendance!$B$2:$B$1201, P8, Attendance!$E$2:$E$1201, "Absent") -> 3 | S8: =COUNTIFS(Attendance!$B$2:$B$1201, P8, Attendance!$E$2:$E$1201, "Leave") -> 0 | T8: =COUNTIFS(Attendance!$B$2:$B$1201, P8, Attendance!$E$2:$E$1201, "Half Day") -> 0 | U8: =ROUND((Q8 + T8*0.5) / (Q8+R8+S8+T8) * 100, 1) -> 90
A9: EMP008 | B9: Pooja Iyer | C9: Female | D9: Finance | E9: Finance Manager | F9: 27-08-2019 | G9: pooja.iyer@coffeecore.com | H9: 9876543217 | I9: 60000 | J9: Active | M9: Phone Number | N9: =_xlfn.XLOOKUP($N$2, tbl_Employee[Employee ID], tbl_Employee[Phone Number]) -> 9876543220 | P9: EMP008 | Q9: =COUNTIFS(Attendance!$B$2:$B$1201, P9, Attendance!$E$2:$E$1201, "Present") -> 22 | R9: =COUNTIFS(Attendance!$B$2:$B$1201, P9, Attendance!$E$2:$E$1201, "Absent") -> 4 | S9: =COUNTIFS(Attendance!$B$2:$B$1201, P9, Attendance!$E$2:$E$1201, "Leave") -> 4 | T9: =COUNTIFS(Attendance!$B$2:$B$1201, P9, Attendance!$E$2:$E$1201, "Half Day") -> 0 | U9: =ROUND((Q9 + T9*0.5) / (Q9+R9+S9+T9) * 100, 1) -> 73.3
A10: EMP009 | B10: Rahul Kapoor | C10: Male | D10: HR | E10: HR Manager | F10: 42982 | G10: rahul.kapoor@coffeecore.com | H10: 9876543218 | I10: 58000 | J10: Active | M10: Salary | N10: =_xlfn.XLOOKUP($N$2, tbl_Employee[Employee ID], tbl_Employee[Salary]) -> 44000 | P10: EMP009 | Q10: =COUNTIFS(Attendance!$B$2:$B$1201, P10, Attendance!$E$2:$E$1201, "Present") -> 25 | R10: =COUNTIFS(Attendance!$B$2:$B$1201, P10, Attendance!$E$2:$E$1201, "Absent") -> 1 | S10: =COUNTIFS(Attendance!$B$2:$B$1201, P10, Attendance!$E$2:$E$1201, "Leave") -> 4 | T10: =COUNTIFS(Attendance!$B$2:$B$1201, P10, Attendance!$E$2:$E$1201, "Half Day") -> 0 | U10: =ROUND((Q10 + T10*0.5) / (Q10+R10+S10+T10) * 100, 1) -> 83.3
A11: EMP010 | B11: Neha Reddy | C11: Female | D11: Operations | E11: Operations Manager | F11: 15-12-2020 | G11: neha.reddy@coffeecore.com | H11: 9876543219 | I11: 56000 | J11: Active | M11: Employment Status | N11: =_xlfn.XLOOKUP($N$2, tbl_Employee[Employee ID], tbl_Employee[Employment Status]) -> Active | P11: EMP010 | Q11: =COUNTIFS(Attendance!$B$2:$B$1201, P11, Attendance!$E$2:$E$1201, "Present") -> 26 | R11: =COUNTIFS(Attendance!$B$2:$B$1201, P11, Attendance!$E$2:$E$1201, "Absent") -> 3 | S11: =COUNTIFS(Attendance!$B$2:$B$1201, P11, Attendance!$E$2:$E$1201, "Leave") -> 1 | T11: =COUNTIFS(Attendance!$B$2:$B$1201, P11, Attendance!$E$2:$E$1201, "Half Day") -> 0 | U11: =ROUND((Q11 + T11*0.5) / (Q11+R11+S11+T11) * 100, 1) -> 86.7
A12: EMP011 | B12: Arjun Desai | C12: Male | D12: IT | E12: Software Engineer | F12: 21-05-2022 | G12: arjun.desai@coffeecore.com | H12: 9876543220 | I12: 44000 | J12: Active | P12: EMP011 | Q12: =COUNTIFS(Attendance!$B$2:$B$1201, P12, Attendance!$E$2:$E$1201, "Present") -> 24 | R12: =COUNTIFS(Attendance!$B$2:$B$1201, P12, Attendance!$E$2:$E$1201, "Absent") -> 3 | S12: =COUNTIFS(Attendance!$B$2:$B$1201, P12, Attendance!$E$2:$E$1201, "Leave") -> 2 | T12: =COUNTIFS(Attendance!$B$2:$B$1201, P12, Attendance!$E$2:$E$1201, "Half Day") -> 1 | U12: =ROUND((Q12 + T12*0.5) / (Q12+R12+S12+T12) * 100, 1) -> 81.7
A13: EMP012 | B13: Divya Pillai | C13: Female | D13: Sales | E13: Sales Executive | F13: 30-10-2021 | G13: divya.pillai@coffeecore.com | H13: 9876543221 | I13: 33000 | J13: Active | P13: EMP012 | Q13: =COUNTIFS(Attendance!$B$2:$B$1201, P13, Attendance!$E$2:$E$1201, "Present") -> 26 | R13: =COUNTIFS(Attendance!$B$2:$B$1201, P13, Attendance!$E$2:$E$1201, "Absent") -> 3 | S13: =COUNTIFS(Attendance!$B$2:$B$1201, P13, Attendance!$E$2:$E$1201, "Leave") -> 1 | T13: =COUNTIFS(Attendance!$B$2:$B$1201, P13, Attendance!$E$2:$E$1201, "Half Day") -> 0 | U13: =ROUND((Q13 + T13*0.5) / (Q13+R13+S13+T13) * 100, 1) -> 86.7
A14: EMP013 | B14: Manish Joshi | C14: Male | D14: Finance | E14: Financial Analyst | F14: 45231 | G14: manish.joshi@coffeecore.com | H14: 9876543222 | I14: 40000 | J14: Active | P14: EMP013 | Q14: =COUNTIFS(Attendance!$B$2:$B$1201, P14, Attendance!$E$2:$E$1201, "Present") -> 25 | R14: =COUNTIFS(Attendance!$B$2:$B$1201, P14, Attendance!$E$2:$E$1201, "Absent") -> 0 | S14: =COUNTIFS(Attendance!$B$2:$B$1201, P14, Attendance!$E$2:$E$1201, "Leave") -> 4 | T14: =COUNTIFS(Attendance!$B$2:$B$1201, P14, Attendance!$E$2:$E$1201, "Half Day") -> 1 | U14: =ROUND((Q14 + T14*0.5) / (Q14+R14+S14+T14) * 100, 1) -> 85
A15: EMP014 | B15: Ritu Choudhary | C15: Female | D15: HR | E15: HR Executive | F15: 25-07-2022 | G15: ritu.choudhary@coffeecore.com | H15: 9876543223 | I15: 37000 | J15: Active | P15: EMP014 | Q15: =COUNTIFS(Attendance!$B$2:$B$1201, P15, Attendance!$E$2:$E$1201, "Present") -> 26 | R15: =COUNTIFS(Attendance!$B$2:$B$1201, P15, Attendance!$E$2:$E$1201, "Absent") -> 2 | S15: =COUNTIFS(Attendance!$B$2:$B$1201, P15, Attendance!$E$2:$E$1201, "Leave") -> 2 | T15: =COUNTIFS(Attendance!$B$2:$B$1201, P15, Attendance!$E$2:$E$1201, "Half Day") -> 0 | U15: =ROUND((Q15 + T15*0.5) / (Q15+R15+S15+T15) * 100, 1) -> 86.7
A16: EMP015 | B16: Saurabh Tiwari | C16: Male | D16: Operations | E16: Operations Executive | F16: 44411 | G16: saurabh.tiwari@coffeecore.com | H16: 9876543224 | I16: 35000 | J16: Active | P16: EMP015 | Q16: =COUNTIFS(Attendance!$B$2:$B$1201, P16, Attendance!$E$2:$E$1201, "Present") -> 28 | R16: =COUNTIFS(Attendance!$B$2:$B$1201, P16, Attendance!$E$2:$E$1201, "Absent") -> 2 | S16: =COUNTIFS(Attendance!$B$2:$B$1201, P16, Attendance!$E$2:$E$1201, "Leave") -> 0 | T16: =COUNTIFS(Attendance!$B$2:$B$1201, P16, Attendance!$E$2:$E$1201, "Half Day") -> 0 | U16: =ROUND((Q16 + T16*0.5) / (Q16+R16+S16+T16) * 100, 1) -> 93.3
A17: EMP016 | B17: Kavita Bhatt | C17: Female | D17: IT | E17: QA Engineer | F17: 19-09-2020 | G17: kavita.bhatt@coffeecore.com | H17: 9876543225 | I17: 41000 | J17: Active | P17: EMP016 | Q17: =COUNTIFS(Attendance!$B$2:$B$1201, P17, Attendance!$E$2:$E$1201, "Present") -> 25 | R17: =COUNTIFS(Attendance!$B$2:$B$1201, P17, Attendance!$E$2:$E$1201, "Absent") -> 4 | S17: =COUNTIFS(Attendance!$B$2:$B$1201, P17, Attendance!$E$2:$E$1201, "Leave") -> 1 | T17: =COUNTIFS(Attendance!$B$2:$B$1201, P17, Attendance!$E$2:$E$1201, "Half Day") -> 0 | U17: =ROUND((Q17 + T17*0.5) / (Q17+R17+S17+T17) * 100, 1) -> 83.3
A18: EMP017 | B18: Deepak Rana | C18: Male | D18: Sales | E18: Sales Associate | F18: 45324 | G18: deepak.rana@coffeecore.com | H18: 9876543226 | I18: 28000 | J18: Active | P18: EMP017 | Q18: =COUNTIFS(Attendance!$B$2:$B$1201, P18, Attendance!$E$2:$E$1201, "Present") -> 27 | R18: =COUNTIFS(Attendance!$B$2:$B$1201, P18, Attendance!$E$2:$E$1201, "Absent") -> 1 | S18: =COUNTIFS(Attendance!$B$2:$B$1201, P18, Attendance!$E$2:$E$1201, "Leave") -> 1 | T18: =COUNTIFS(Attendance!$B$2:$B$1201, P18, Attendance!$E$2:$E$1201, "Half Day") -> 1 | U18: =ROUND((Q18 + T18*0.5) / (Q18+R18+S18+T18) * 100, 1) -> 91.7
A19: EMP018 | B19: Shruti Agarwal | C19: Female | D19: Finance | E19: Accountant | F19: 16-06-2021 | G19: shruti.agarwal@coffeecore.com | H19: 9876543227 | I19: 39000 | J19: Active | P19: EMP018 | Q19: =COUNTIFS(Attendance!$B$2:$B$1201, P19, Attendance!$E$2:$E$1201, "Present") -> 24 | R19: =COUNTIFS(Attendance!$B$2:$B$1201, P19, Attendance!$E$2:$E$1201, "Absent") -> 3 | S19: =COUNTIFS(Attendance!$B$2:$B$1201, P19, Attendance!$E$2:$E$1201, "Leave") -> 3 | T19: =COUNTIFS(Attendance!$B$2:$B$1201, P19, Attendance!$E$2:$E$1201, "Half Day") -> 0 | U19: =ROUND((Q19 + T19*0.5) / (Q19+R19+S19+T19) * 100, 1) -> 80
A20: EMP019 | B20: Nikhil Bose | C20: Male | D20: HR | E20: Recruiter | F20: 23-11-2022 | G20: nikhil.bose@coffeecore.com | H20: 9876543228 | I20: 34000 | J20: Active | P20: EMP019 | Q20: =COUNTIFS(Attendance!$B$2:$B$1201, P20, Attendance!$E$2:$E$1201, "Present") -> 24 | R20: =COUNTIFS(Attendance!$B$2:$B$1201, P20, Attendance!$E$2:$E$1201, "Absent") -> 4 | S20: =COUNTIFS(Attendance!$B$2:$B$1201, P20, Attendance!$E$2:$E$1201, "Leave") -> 2 | T20: =COUNTIFS(Attendance!$B$2:$B$1201, P20, Attendance!$E$2:$E$1201, "Half Day") -> 0 | U20: =ROUND((Q20 + T20*0.5) / (Q20+R20+S20+T20) * 100, 1) -> 80
A21: EMP020 | B21: Meera Krishnan | C21: Female | D21: Operations | E21: Operations Associate | F21: 45111 | G21: meera.krishnan@coffeecore.com | H21: 9876543229 | I21: 30000 | J21: Active | P21: EMP020 | Q21: =COUNTIFS(Attendance!$B$2:$B$1201, P21, Attendance!$E$2:$E$1201, "Present") -> 28 | R21: =COUNTIFS(Attendance!$B$2:$B$1201, P21, Attendance!$E$2:$E$1201, "Absent") -> 1 | S21: =COUNTIFS(Attendance!$B$2:$B$1201, P21, Attendance!$E$2:$E$1201, "Leave") -> 1 | T21: =COUNTIFS(Attendance!$B$2:$B$1201, P21, Attendance!$E$2:$E$1201, "Half Day") -> 0 | U21: =ROUND((Q21 + T21*0.5) / (Q21+R21+S21+T21) * 100, 1) -> 93.3
A22: EMP021 | B22: Suresh Yadav | C22: Male | D22: IT | E22: DevOps Engineer | F22: 13-08-2019 | G22: suresh.yadav@coffeecore.com | H22: 9876543230 | I22: 48000 | J22: Active | P22: EMP021 | Q22: =COUNTIFS(Attendance!$B$2:$B$1201, P22, Attendance!$E$2:$E$1201, "Present") -> 27 | R22: =COUNTIFS(Attendance!$B$2:$B$1201, P22, Attendance!$E$2:$E$1201, "Absent") -> 2 | S22: =COUNTIFS(Attendance!$B$2:$B$1201, P22, Attendance!$E$2:$E$1201, "Leave") -> 1 | T22: =COUNTIFS(Attendance!$B$2:$B$1201, P22, Attendance!$E$2:$E$1201, "Half Day") -> 0 | U22: =ROUND((Q22 + T22*0.5) / (Q22+R22+S22+T22) * 100, 1) -> 90
A23: EMP022 | B23: Tanvi Shetty | C23: Female | D23: Sales | E23: Sales Executive | F23: 29-12-2022 | G23: tanvi.shetty@coffeecore.com | H23: 9876543231 | I23: 33000 | J23: Resigned | P23: EMP022 | Q23: =COUNTIFS(Attendance!$B$2:$B$1201, P23, Attendance!$E$2:$E$1201, "Present") -> 26 | R23: =COUNTIFS(Attendance!$B$2:$B$1201, P23, Attendance!$E$2:$E$1201, "Absent") -> 3 | S23: =COUNTIFS(Attendance!$B$2:$B$1201, P23, Attendance!$E$2:$E$1201, "Leave") -> 1 | T23: =COUNTIFS(Attendance!$B$2:$B$1201, P23, Attendance!$E$2:$E$1201, "Half Day") -> 0 | U23: =ROUND((Q23 + T23*0.5) / (Q23+R23+S23+T23) * 100, 1) -> 86.7
A24: EMP023 | B24: Akash Pandey | C24: Male | D24: Finance | E24: Finance Manager | F24: 43195 | G24: akash.pandey@coffeecore.com | H24: 9876543232 | I24: 59000 | J24: Active | P24: EMP023 | Q24: =COUNTIFS(Attendance!$B$2:$B$1201, P24, Attendance!$E$2:$E$1201, "Present") -> 27 | R24: =COUNTIFS(Attendance!$B$2:$B$1201, P24, Attendance!$E$2:$E$1201, "Absent") -> 1 | S24: =COUNTIFS(Attendance!$B$2:$B$1201, P24, Attendance!$E$2:$E$1201, "Leave") -> 2 | T24: =COUNTIFS(Attendance!$B$2:$B$1201, P24, Attendance!$E$2:$E$1201, "Half Day") -> 0 | U24: =ROUND((Q24 + T24*0.5) / (Q24+R24+S24+T24) * 100, 1) -> 90
A25: EMP024 | B25: Swati Mishra | C25: Female | D25: HR | E25: HR Executive | F25: 17-10-2021 | G25: swati.mishra@coffeecore.com | H25: 9876543233 | I25: 36000 | J25: Active | P25: EMP024 | Q25: =COUNTIFS(Attendance!$B$2:$B$1201, P25, Attendance!$E$2:$E$1201, "Present") -> 26 | R25: =COUNTIFS(Attendance!$B$2:$B$1201, P25, Attendance!$E$2:$E$1201, "Absent") -> 4 | S25: =COUNTIFS(Attendance!$B$2:$B$1201, P25, Attendance!$E$2:$E$1201, "Leave") -> 0 | T25: =COUNTIFS(Attendance!$B$2:$B$1201, P25, Attendance!$E$2:$E$1201, "Half Day") -> 0 | U25: =ROUND((Q25 + T25*0.5) / (Q25+R25+S25+T25) * 100, 1) -> 86.7
A26: EMP025 | B26: Gaurav Saxena | C26: Male | D26: Operations | E26: Operations Executive | F26: 26-01-2022 | G26: gaurav.saxena@coffeecore.com | H26: 9876543234 | I26: 35000 | J26: Active | P26: EMP025 | Q26: =COUNTIFS(Attendance!$B$2:$B$1201, P26, Attendance!$E$2:$E$1201, "Present") -> 29 | R26: =COUNTIFS(Attendance!$B$2:$B$1201, P26, Attendance!$E$2:$E$1201, "Absent") -> 1 | S26: =COUNTIFS(Attendance!$B$2:$B$1201, P26, Attendance!$E$2:$E$1201, "Leave") -> 0 | T26: =COUNTIFS(Attendance!$B$2:$B$1201, P26, Attendance!$E$2:$E$1201, "Half Day") -> 0 | U26: =ROUND((Q26 + T26*0.5) / (Q26+R26+S26+T26) * 100, 1) -> 96.7
A27: EMP026 | B27: Isha Kulkarni | C27: Female | D27: IT | E27: Software Engineer | F27: 45175 | G27: isha.kulkarni@coffeecore.com | H27: 9876543235 | I27: 43000 | J27: Active | P27: EMP026 | Q27: =COUNTIFS(Attendance!$B$2:$B$1201, P27, Attendance!$E$2:$E$1201, "Present") -> 25 | R27: =COUNTIFS(Attendance!$B$2:$B$1201, P27, Attendance!$E$2:$E$1201, "Absent") -> 3 | S27: =COUNTIFS(Attendance!$B$2:$B$1201, P27, Attendance!$E$2:$E$1201, "Leave") -> 1 | T27: =COUNTIFS(Attendance!$B$2:$B$1201, P27, Attendance!$E$2:$E$1201, "Half Day") -> 1 | U27: =ROUND((Q27 + T27*0.5) / (Q27+R27+S27+T27) * 100, 1) -> 85
A28: EMP027 | B28: Vivek Chauhan | C28: Male | D28: Sales | E28: Sales Manager | F28: 44167 | G28: vivek.chauhan@coffeecore.com | H28: 9876543236 | I28: 54000 | J28: Active | P28: EMP027 | Q28: =COUNTIFS(Attendance!$B$2:$B$1201, P28, Attendance!$E$2:$E$1201, "Present") -> 26 | R28: =COUNTIFS(Attendance!$B$2:$B$1201, P28, Attendance!$E$2:$E$1201, "Absent") -> 2 | S28: =COUNTIFS(Attendance!$B$2:$B$1201, P28, Attendance!$E$2:$E$1201, "Leave") -> 2 | T28: =COUNTIFS(Attendance!$B$2:$B$1201, P28, Attendance!$E$2:$E$1201, "Half Day") -> 0 | U28: =ROUND((Q28 + T28*0.5) / (Q28+R28+S28+T28) * 100, 1) -> 86.7
A29: EMP028 | B29: Anushka Menon | C29: Female | D29: Finance | E29: Financial Analyst | F29: 20-09-2022 | G29: anushka.menon@coffeecore.com | H29: 9876543237 | I29: 40000 | J29: Active | P29: EMP028 | Q29: =COUNTIFS(Attendance!$B$2:$B$1201, P29, Attendance!$E$2:$E$1201, "Present") -> 22 | R29: =COUNTIFS(Attendance!$B$2:$B$1201, P29, Attendance!$E$2:$E$1201, "Absent") -> 7 | S29: =COUNTIFS(Attendance!$B$2:$B$1201, P29, Attendance!$E$2:$E$1201, "Leave") -> 1 | T29: =COUNTIFS(Attendance!$B$2:$B$1201, P29, Attendance!$E$2:$E$1201, "Half Day") -> 0 | U29: =ROUND((Q29 + T29*0.5) / (Q29+R29+S29+T29) * 100, 1) -> 73.3
A30: EMP029 | B30: Harsh Vardhan | C30: Male | D30: HR | E30: Recruiter | F30: 44262 | G30: harsh.vardhan@coffeecore.com | H30: 9876543238 | I30: 33000 | J30: Active | P30: EMP029 | Q30: =COUNTIFS(Attendance!$B$2:$B$1201, P30, Attendance!$E$2:$E$1201, "Present") -> 28 | R30: =COUNTIFS(Attendance!$B$2:$B$1201, P30, Attendance!$E$2:$E$1201, "Absent") -> 1 | S30: =COUNTIFS(Attendance!$B$2:$B$1201, P30, Attendance!$E$2:$E$1201, "Leave") -> 1 | T30: =COUNTIFS(Attendance!$B$2:$B$1201, P30, Attendance!$E$2:$E$1201, "Half Day") -> 0 | U30: =ROUND((Q30 + T30*0.5) / (Q30+R30+S30+T30) * 100, 1) -> 93.3
A31: EMP030 | B31: Pallavi Rao | C31: Female | D31: Operations | E31: Operations Manager | F31: 14-03-2019 | G31: pallavi.rao@coffeecore.com | H31: 9876543239 | I31: 57000 | J31: Active | P31: EMP030 | Q31: =COUNTIFS(Attendance!$B$2:$B$1201, P31, Attendance!$E$2:$E$1201, "Present") -> 27 | R31: =COUNTIFS(Attendance!$B$2:$B$1201, P31, Attendance!$E$2:$E$1201, "Absent") -> 2 | S31: =COUNTIFS(Attendance!$B$2:$B$1201, P31, Attendance!$E$2:$E$1201, "Leave") -> 1 | T31: =COUNTIFS(Attendance!$B$2:$B$1201, P31, Attendance!$E$2:$E$1201, "Half Day") -> 0 | U31: =ROUND((Q31 + T31*0.5) / (Q31+R31+S31+T31) * 100, 1) -> 90
A32: EMP031 | B32: Sandeep Kumar | C32: Male | D32: IT | E32: IT Manager | F32: 28-11-2017 | G32: sandeep.kumar@coffeecore.com | H32: 9876543240 | I32: 63000 | J32: Active | P32: EMP031 | Q32: =COUNTIFS(Attendance!$B$2:$B$1201, P32, Attendance!$E$2:$E$1201, "Present") -> 26 | R32: =COUNTIFS(Attendance!$B$2:$B$1201, P32, Attendance!$E$2:$E$1201, "Absent") -> 2 | S32: =COUNTIFS(Attendance!$B$2:$B$1201, P32, Attendance!$E$2:$E$1201, "Leave") -> 2 | T32: =COUNTIFS(Attendance!$B$2:$B$1201, P32, Attendance!$E$2:$E$1201, "Half Day") -> 0 | U32: =ROUND((Q32 + T32*0.5) / (Q32+R32+S32+T32) * 100, 1) -> 86.7
A33: EMP032 | B33: Aditi Bansal | C33: Female | D33: Sales | E33: Sales Associate | F33: 45448 | G33: aditi.bansal@coffeecore.com | H33: 9876543241 | I33: 27000 | J33: Active | P33: EMP032 | Q33: =COUNTIFS(Attendance!$B$2:$B$1201, P33, Attendance!$E$2:$E$1201, "Present") -> 26 | R33: =COUNTIFS(Attendance!$B$2:$B$1201, P33, Attendance!$E$2:$E$1201, "Absent") -> 4 | S33: =COUNTIFS(Attendance!$B$2:$B$1201, P33, Attendance!$E$2:$E$1201, "Leave") -> 0 | T33: =COUNTIFS(Attendance!$B$2:$B$1201, P33, Attendance!$E$2:$E$1201, "Half Day") -> 0 | U33: =ROUND((Q33 + T33*0.5) / (Q33+R33+S33+T33) * 100, 1) -> 86.7
A34: EMP033 | B34: Rajesh Khanna | C34: Male | D34: Finance | E34: Accountant | F34: 44145 | G34: rajesh.khanna@coffeecore.com | H34: 9876543242 | I34: 41000 | J34: Resigned | P34: EMP033 | Q34: =COUNTIFS(Attendance!$B$2:$B$1201, P34, Attendance!$E$2:$E$1201, "Present") -> 25 | R34: =COUNTIFS(Attendance!$B$2:$B$1201, P34, Attendance!$E$2:$E$1201, "Absent") -> 2 | S34: =COUNTIFS(Attendance!$B$2:$B$1201, P34, Attendance!$E$2:$E$1201, "Leave") -> 2 | T34: =COUNTIFS(Attendance!$B$2:$B$1201, P34, Attendance!$E$2:$E$1201, "Half Day") -> 1 | U34: =ROUND((Q34 + T34*0.5) / (Q34+R34+S34+T34) * 100, 1) -> 85
A35: EMP034 | B35: Komal Thakur | C35: Female | D35: HR | E35: HR Manager | F35: 22-04-2018 | G35: komal.thakur@coffeecore.com | H35: 9876543243 | I35: 59000 | J35: Active | P35: EMP034 | Q35: =COUNTIFS(Attendance!$B$2:$B$1201, P35, Attendance!$E$2:$E$1201, "Present") -> 28 | R35: =COUNTIFS(Attendance!$B$2:$B$1201, P35, Attendance!$E$2:$E$1201, "Absent") -> 1 | S35: =COUNTIFS(Attendance!$B$2:$B$1201, P35, Attendance!$E$2:$E$1201, "Leave") -> 1 | T35: =COUNTIFS(Attendance!$B$2:$B$1201, P35, Attendance!$E$2:$E$1201, "Half Day") -> 0 | U35: =ROUND((Q35 + T35*0.5) / (Q35+R35+S35+T35) * 100, 1) -> 93.3
A36: EMP035 | B36: Yash Chopra | C36: Male | D36: Operations | E36: Operations Associate | F36: 15-08-2023 | G36: yash.chopra@coffeecore.com | H36: 9876543244 | I36: 29000 | J36: Active | P36: EMP035 | Q36: =COUNTIFS(Attendance!$B$2:$B$1201, P36, Attendance!$E$2:$E$1201, "Present") -> 24 | R36: =COUNTIFS(Attendance!$B$2:$B$1201, P36, Attendance!$E$2:$E$1201, "Absent") -> 4 | S36: =COUNTIFS(Attendance!$B$2:$B$1201, P36, Attendance!$E$2:$E$1201, "Leave") -> 2 | T36: =COUNTIFS(Attendance!$B$2:$B$1201, P36, Attendance!$E$2:$E$1201, "Half Day") -> 0 | U36: =ROUND((Q36 + T36*0.5) / (Q36+R36+S36+T36) * 100, 1) -> 80
A37: EMP036 | B37: Riya Dutta | C37: Female | D37: IT | E37: QA Engineer | F37: 44562 | G37: riya.dutta@coffeecore.com | H37: 9876543245 | I37: 40000 | J37: Active | P37: EMP036 | Q37: =COUNTIFS(Attendance!$B$2:$B$1201, P37, Attendance!$E$2:$E$1201, "Present") -> 27 | R37: =COUNTIFS(Attendance!$B$2:$B$1201, P37, Attendance!$E$2:$E$1201, "Absent") -> 2 | S37: =COUNTIFS(Attendance!$B$2:$B$1201, P37, Attendance!$E$2:$E$1201, "Leave") -> 1 | T37: =COUNTIFS(Attendance!$B$2:$B$1201, P37, Attendance!$E$2:$E$1201, "Half Day") -> 0 | U37: =ROUND((Q37 + T37*0.5) / (Q37+R37+S37+T37) * 100, 1) -> 90
A38: EMP037 | B38: Mohit Sinha | C38: Male | D38: Sales | E38: Sales Executive | F38: 44448 | G38: mohit.sinha@coffeecore.com | H38: 9876543246 | I38: 34000 | J38: Active | P38: EMP037 | Q38: =COUNTIFS(Attendance!$B$2:$B$1201, P38, Attendance!$E$2:$E$1201, "Present") -> 22 | R38: =COUNTIFS(Attendance!$B$2:$B$1201, P38, Attendance!$E$2:$E$1201, "Absent") -> 7 | S38: =COUNTIFS(Attendance!$B$2:$B$1201, P38, Attendance!$E$2:$E$1201, "Leave") -> 1 | T38: =COUNTIFS(Attendance!$B$2:$B$1201, P38, Attendance!$E$2:$E$1201, "Half Day") -> 0 | U38: =ROUND((Q38 + T38*0.5) / (Q38+R38+S38+T38) * 100, 1) -> 73.3
A39: EMP038 | B39: Preeti Joshi | C39: Female | D39: Finance | E39: Finance Manager | F39: 18-02-2019 | G39: preeti.joshi@coffeecore.com | H39: 9876543247 | I39: 61000 | J39: Active | P39: EMP038 | Q39: =COUNTIFS(Attendance!$B$2:$B$1201, P39, Attendance!$E$2:$E$1201, "Present") -> 22 | R39: =COUNTIFS(Attendance!$B$2:$B$1201, P39, Attendance!$E$2:$E$1201, "Absent") -> 7 | S39: =COUNTIFS(Attendance!$B$2:$B$1201, P39, Attendance!$E$2:$E$1201, "Leave") -> 1 | T39: =COUNTIFS(Attendance!$B$2:$B$1201, P39, Attendance!$E$2:$E$1201, "Half Day") -> 0 | U39: =ROUND((Q39 + T39*0.5) / (Q39+R39+S39+T39) * 100, 1) -> 73.3
A40: EMP039 | B40: Abhishek Roy | C40: Male | D40: HR | E40: HR Executive | F40: 24-06-2023 | G40: abhishek.roy@coffeecore.com | H40: 9876543248 | I40: 35000 | J40: Active | P40: EMP039 | Q40: =COUNTIFS(Attendance!$B$2:$B$1201, P40, Attendance!$E$2:$E$1201, "Present") -> 26 | R40: =COUNTIFS(Attendance!$B$2:$B$1201, P40, Attendance!$E$2:$E$1201, "Absent") -> 3 | S40: =COUNTIFS(Attendance!$B$2:$B$1201, P40, Attendance!$E$2:$E$1201, "Leave") -> 1 | T40: =COUNTIFS(Attendance!$B$2:$B$1201, P40, Attendance!$E$2:$E$1201, "Half Day") -> 0 | U40: =ROUND((Q40 + T40*0.5) / (Q40+R40+S40+T40) * 100, 1) -> 86.7
...

Sheet Attendance
A1: Date | B1: Employee ID | C1: Employee Name | D1: Department | E1: Attendance Status
A2: 46174 | B2: EMP001 | C2: Rohan Mehta | D2: IT | E2: Present
A3: 46174 | B3: EMP002 | C3: Priya Sharma | D3: HR | E3: Present
A4: 46174 | B4: EMP003 | C4: Aman Gupta | D4: Sales | E4: Present
A5: 46174 | B5: EMP004 | C5: Sneha Verma | D5: Finance | E5: Present
A6: 46174 | B6: EMP005 | C6: Vikram Singh | D6: Operations | E6: Present
A7: 46174 | B7: EMP006 | C7: Anjali Nair | D7: IT | E7: Present
A8: 46174 | B8: EMP007 | C8: Karan Malhotra | D8: Sales | E8: Present
A9: 46174 | B9: EMP008 | C9: Pooja Iyer | D9: Finance | E9: Leave
A10: 46174 | B10: EMP009 | C10: Rahul Kapoor | D10: HR | E10: Present
A11: 46174 | B11: EMP010 | C11: Neha Reddy | D11: Operations | E11: Present
A12: 46174 | B12: EMP011 | C12: Arjun Desai | D12: IT | E12: Leave
A13: 46174 | B13: EMP012 | C13: Divya Pillai | D13: Sales | E13: Absent
... A1201: 46203 | B1201: EMP040 | C1201: Sunita Bhatia | D1201: Operations | E1201: Present

Sheet Leave_Management
A1: Leave ID | B1: Employee ID | C1: Employee Name | D1: Leave Type | E1: Start Date | F1: End Date | G1: Total Days | H1: Approval Status | J1: EMPLOYEE LEAVE HISTORY
A2: LV001 | B2: EMP001 | C2: Rohan Mehta | D2: Casual Leave | E2: 46176 | F2: 46177 | G2: =(F2-E2)+1 -> 2 | H2: Approved | J2: Enter Employee ID | K2: EMP012
A3: LV002 | B3: EMP003 | C3: Aman Gupta | D3: Sick Leave | E3: 46178 | F3: 46178 | G3: =(F3-E3)+1 -> 1 | H3: Approved | J3: Total Leaves Taken | K3: =COUNTIF(tbl_Leave[Employee ID],"EMP001") -> 1 | N3: =1+1 -> 2
A4: LV003 | B4: EMP007 | C4: Karan Malhotra | D4: Casual Leave | E4: 46174 | F4: 46174 | G4: =(F4-E4)+1 -> 1 | H4: Approved | J4: Total Days Taken | K4: =SUMIFS(tbl_Leave[Total Days],tbl_Leave[Employee ID],K2) -> 2
A5: LV004 | B5: EMP010 | C5: Neha Reddy | D5: Emergency Leave | E5: 46183 | F5: 46184 | G5: =(F5-E5)+1 -> 2 | H5: Pending | J5: Approved Leaves | K5: =COUNTIFS(tbl_Leave[Employee ID],K2,tbl_Leave[Approval Status],"Approved") -> 1
A6: LV005 | B6: EMP012 | C6: Divya Pillai | D6: Sick Leave | E6: 46181 | F6: 46182 | G6: =(F6-E6)+1 -> 2 | H6: Approved | J6: Pending Leaves | K6: =COUNTIFS(tbl_Leave[Employee ID],K2,tbl_Leave[Approval Status],"Pending") -> 0
A7: LV006 | B7: EMP015 | C7: Saurabh Tiwari | D7: Casual Leave | E7: 46175 | F7: 46175 | G7: =(F7-E7)+1 -> 1 | H7: Approved
A8: LV007 | B8: EMP019 | C8: Nikhil Bose | D8: Casual Leave | E8: 46179 | F8: 46179 | G8: =(F8-E8)+1 -> 1 | H8: Approved
A9: LV008 | B9: EMP022 | C9: Tanvi Shetty | D9: Sick Leave | E9: 46185 | F9: 46187 | G9: =(F9-E9)+1 -> 3 | H9: Approved
A10: LV009 | B10: EMP004 | C10: Sneha Verma | D10: Emergency Leave | E10: 46177 | F10: 46177 | G10: =(F10-E10)+1 -> 1 | H10: Pending
A11: LV010 | B11: EMP028 | C11: Anushka Menon | D11: Casual Leave | E11: 46188 | F11: 46189 | G11: =(F11-E11)+1 -> 2 | H11: Approved
A12: LV011 | B12: EMP032 | C12: Aditi Bansal | D12: Casual Leave | E12: 46180 | F12: 46180 | G12: =(F12-E12)+1 -> 1 | H12: Approved
A13: LV012 | B13: EMP039 | C13: Abhishek Roy | D13: Sick Leave | E13: 46182 | F13: 46183 | G13: =(F13-E13)+1 -> 2 | H13: Rejected
A14: LV013 | B14: EMP005 | C14: Vikram Singh | D14: Casual Leave | E14: 46184 | F14: 46184 | G14: =(F14-E14)+1 -> 1 | H14: Approved
A15: LV014 | B15: EMP017 | C15: Deepak Rana | D15: Sick Leave | E15: 46186 | F15: 46186 | G15: =(F15-E15)+1 -> 1 | H15: Approved
A16: LV015 | B16: EMP024 | C16: Swati Mishra | D16: Emergency Leave | E16: 46190 | F16: 46191 | G16: =(F16-E16)+1 -> 2 | H16: Pending
A17: LV016 | B17: EMP002 | C17: Priya Sharma | D17: Casual Leave | E17: 46179 | F17: 46179 | G17: =(F17-E17)+1 -> 1 | H17: Approved
A18: LV017 | B18: EMP011 | C18: Arjun Desai | D18: Sick Leave | E18: 46187 | F18: 46188 | G18: =(F18-E18)+1 -> 2 | H18: Approved
... A29: LV028 | B29: EMP006 | C29: Anjali Nair | D29: Casual Leave | E29: 46196 | F29: 46196 | G29: =(F29-E29)+1 -> 1 | H29: Rejected

Sheet Payroll
A1: Employee ID | B1: Basic Salary | C1: Attendance | D1: Leave Deduction | E1: Bonus | F1: Net Salary
A2: {=tbl_Employee[Employee ID]} -> EMP001 | B2: =_xlfn.XLOOKUP(A2, tbl_Employee[Employee ID], tbl_Employee[Salary]) -> 45000 | C2: =_xlfn.XLOOKUP(A2, Employee_Database!P:P, Employee_Database!U:U) -> 86.7 | D2: =ROUND(B2*(100-C2)/100*0.5,0) -> 2993 | E2: =IF(C2>=95,B2*0.1,IF(C2>=85,B2*0.05,0)) -> 2250 | F2: =B2+E2-D2 -> 44257
A3: EMP002 | B3: =_xlfn.XLOOKUP(A3, tbl_Employee[Employee ID], tbl_Employee[Salary]) -> 38000 | C3: =_xlfn.XLOOKUP(A3, Employee_Database!P:P, Employee_Database!U:U) -> 80 | D3: =ROUND(B3*(100-C3)/100*0.5,0) -> 3800 | E3: =IF(C3>=95,B3*0.1,IF(C3>=85,B3*0.05,0)) -> 0 | F3: =B3+E3-D3 -> 34200
A4: EMP003 | B4: =_xlfn.XLOOKUP(A4, tbl_Employee[Employee ID], tbl_Employee[Salary]) -> 55000 | C4: =_xlfn.XLOOKUP(A4, Employee_Database!P:P, Employee_Database!U:U) -> 91.7 | D4: =ROUND(B4*(100-C4)/100*0.5,0) -> 2283 | E4: =IF(C4>=95,B4*0.1,IF(C4>=85,B4*0.05,0)) -> 2750 | F4: =B4+E4-D4 -> 55467
A5: EMP004 | B5: =_xlfn.XLOOKUP(A5, tbl_Employee[Employee ID], tbl_Employee[Salary]) -> 42000 | C5: =_xlfn.XLOOKUP(A5, Employee_Database!P:P, Employee_Database!U:U) -> 80 | D5: =ROUND(B5*(100-C5)/100*0.5,0) -> 4200 | E5: =IF(C5>=95,B5*0.1,IF(C5>=85,B5*0.05,0)) -> 0 | F5: =B5+E5-D5 -> 37800
A6: EMP005 | B6: =_xlfn.XLOOKUP(A6, tbl_Employee[Employee ID], tbl_Employee[Salary]) -> 36000 | C6: =_xlfn.XLOOKUP(A6, Employee_Database!P:P, Employee_Database!U:U) -> 88.3 | D6: =ROUND(B6*(100-C6)/100*0.5,0) -> 2106 | E6: =IF(C6>=95,B6*0.1,IF(C6>=85,B6*0.05,0)) -> 1800 | F6: =B6+E6-D6 -> 35694
A7: EMP006 | B7: =_xlfn.XLOOKUP(A7, tbl_Employee[Employee ID], tbl_Employee[Salary]) -> 62000 | C7: =_xlfn.XLOOKUP(A7, Employee_Database!P:P, Employee_Database!U:U) -> 85 | D7: =ROUND(B7*(100-C7)/100*0.5,0) -> 4650 | E7: =IF(C7>=95,B7*0.1,IF(C7>=85,B7*0.05,0)) -> 3100 | F7: =B7+E7-D7 -> 60450
A8: EMP007 | B8: =_xlfn.XLOOKUP(A8, tbl_Employee[Employee ID], tbl_Employee[Salary]) -> 32000 | C8: =_xlfn.XLOOKUP(A8, Employee_Database!P:P, Employee_Database!U:U) -> 90 | D8: =ROUND(B8*(100-C8)/100*0.5,0) -> 1600 | E8: =IF(C8>=95,B8*0.1,IF(C8>=85,B8*0.05,0)) -> 1600 | F8: =B8+E8-D8 -> 32000
A9: EMP008 | B9: =_xlfn.XLOOKUP(A9, tbl_Employee[Employee ID], tbl_Employee[Salary]) -> 60000 | C9: =_xlfn.XLOOKUP(A9, Employee_Database!P:P, Employee_Database!U:U) -> 73.3 | D9: =ROUND(B9*(100-C9)/100*0.5,0) -> 8010 | E9: =IF(C9>=95,B9*0.1,IF(C9>=85,B9*0.05,0)) -> 0 | F9: =B9+E9-D9 -> 51990
A10: EMP009 | B10: =_xlfn.XLOOKUP(A10, tbl_Employee[Employee ID], tbl_Employee[Salary]) -> 58000 | C10: =_xlfn.XLOOKUP(A10, Employee_Database!P:P, Employee_Database!U:U) -> 83.3 | D10: =ROUND(B10*(100-C10)/100*0.5,0) -> 4843 | E10: =IF(C10>=95,B10*0.1,IF(C10>=85,B10*0.05,0)) -> 0 | F10: =B10+E10-D10 -> 53157
A11: EMP010 | B11: =_xlfn.XLOOKUP(A11, tbl_Employee[Employee ID], tbl_Employee[Salary]) -> 56000 | C11: =_xlfn.XLOOKUP(A11, Employee_Database!P:P, Employee_Database!U:U) -> 86.7 | D11: =ROUND(B11*(100-C11)/100*0.5,0) -> 3724 | E11: =IF(C11>=95,B11*0.1,IF(C11>=85,B11*0.05,0)) -> 2800 | F11: =B11+E11-D11 -> 55076
A12: EMP011 | B12: =_xlfn.XLOOKUP(A12, tbl_Employee[Employee ID], tbl_Employee[Salary]) -> 44000 | C12: =_xlfn.XLOOKUP(A12, Employee_Database!P:P, Employee_Database!U:U) -> 81.7 | D12: =ROUND(B12*(100-C12)/100*0.5,0) -> 4026 | E12: =IF(C12>=95,B12*0.1,IF(C12>=85,B12*0.05,0)) -> 0 | F12: =B12+E12-D12 -> 39974
A13: EMP012 | B13: =_xlfn.XLOOKUP(A13, tbl_Employee[Employee ID], tbl_Employee[Salary]) -> 33000 | C13: =_xlfn.XLOOKUP(A13, Employee_Database!P:P, Employee_Database!U:U) -> 86.7 | D13: =ROUND(B13*(100-C13)/100*0.5,0) -> 2195 | E13: =IF(C13>=95,B13*0.1,IF(C13>=85,B13*0.05,0)) -> 1650 | F13: =B13+E13-D13 -> 32455
A14: EMP013 | B14: =_xlfn.XLOOKUP(A14, tbl_Employee[Employee ID], tbl_Employee[Salary]) -> 40000 | C14: =_xlfn.XLOOKUP(A14, Employee_Database!P:P, Employee_Database!U:U) -> 85 | D14: =ROUND(B14*(100-C14)/100*0.5,0) -> 3000 | E14: =IF(C14>=95,B14*0.1,IF(C14>=85,B14*0.05,0)) -> 2000 | F14: =B14+E14-D14 -> 39000
... A41: EMP040 | B41: =_xlfn.XLOOKUP(A41, tbl_Employee[Employee ID], tbl_Employee[Salary]) -> 0 | C41: =_xlfn.XLOOKUP(A41, Employee_Database!P:P, Employee_Database!U:U) -> 83.3 | D41: =ROUND(B41*(100-C41)/100*0.5,0) -> 0 | E41: =IF(C41>=95,B41*0.1,IF(C41>=85,B41*0.05,0)) -> 0 | F41: =B41+E41-D41 -> 0

Sheet Performance
A1: Employee ID | B1: Employee Name | C1: KPI Score | D1: Attendance Score | E1: Productivity Score | F1: Overall Rating
A2: =Employee_Database!A2 -> EMP001 | B2: =_xlfn.XLOOKUP(A2, tbl_Employee[Employee ID], tbl_Employee[Full Name]) -> Rohan Mehta | C2: 83 | D2: =_xlfn.XLOOKUP(A2, Payroll!A:A, Payroll!C:C) -> 86.7 | E2: 76 | F2: =IF(AVERAGE(C2,D2,E2)>=85,"Excellent",IF(AVERAGE(C2,D2,E2)>=70,"Good",IF(AVERAGE(C2,D2,E2)>=55,"Average","Poor"))) -> Good
A3: =Employee_Database!A3 -> EMP002 | B3: =_xlfn.XLOOKUP(A3, tbl_Employee[Employee ID], tbl_Employee[Full Name]) -> Priya Sharma | C3: 61 | D3: =_xlfn.XLOOKUP(A3, Payroll!A:A, Payroll!C:C) -> 80 | E3: 94 | F3: =IF(AVERAGE(C3,D3,E3)>=85,"Excellent",IF(AVERAGE(C3,D3,E3)>=70,"Good",IF(AVERAGE(C3,D3,E3)>=55,"Average","Poor"))) -> Good
A4: =Employee_Database!A4 -> EMP003 | B4: =_xlfn.XLOOKUP(A4, tbl_Employee[Employee ID], tbl_Employee[Full Name]) -> Aman Gupta | C4: 94 | D4: =_xlfn.XLOOKUP(A4, Payroll!A:A, Payroll!C:C) -> 91.7 | E4: 67 | F4: =IF(AVERAGE(C4,D4,E4)>=85,"Excellent",IF(AVERAGE(C4,D4,E4)>=70,"Good",IF(AVERAGE(C4,D4,E4)>=55,"Average","Poor"))) -> Good
A5: =Employee_Database!A5 -> EMP004 | B5: =_xlfn.XLOOKUP(A5, tbl_Employee[Employee ID], tbl_Employee[Full Name]) -> Sneha Verma | C5: 87 | D5: =_xlfn.XLOOKUP(A5, Payroll!A:A, Payroll!C:C) -> 80 | E5: 74 | F5: =IF(AVERAGE(C5,D5,E5)>=85,"Excellent",IF(AVERAGE(C5,D5,E5)>=70,"Good",IF(AVERAGE(C5,D5,E5)>=55,"Average","Poor"))) -> Good
A6: =Employee_Database!A6 -> EMP005 | B6: =_xlfn.XLOOKUP(A6, tbl_Employee[Employee ID], tbl_Employee[Full Name]) -> Vikram Singh | C6: 97 | D6: =_xlfn.XLOOKUP(A6, Payroll!A:A, Payroll!C:C) -> 88.3 | E6: 77 | F6: =IF(AVERAGE(C6,D6,E6)>=85,"Excellent",IF(AVERAGE(C6,D6,E6)>=70,"Good",IF(AVERAGE(C6,D6,E6)>=55,"Average","Poor"))) -> Excellent
A7: =Employee_Database!A7 -> EMP006 | B7: =_xlfn.XLOOKUP(A7, tbl_Employee[Employee ID], tbl_Employee[Full Name]) -> Anjali Nair | C7: 87 | D7: =_xlfn.XLOOKUP(A7, Payroll!A:A, Payroll!C:C) -> 85 | E7: 65 | F7: =IF(AVERAGE(C7,D7,E7)>=85,"Excellent",IF(AVERAGE(C7,D7,E7)>=70,"Good",IF(AVERAGE(C7,D7,E7)>=55,"Average","Poor"))) -> Good
A8: =Employee_Database!A8 -> EMP007 | B8: =_xlfn.XLOOKUP(A8, tbl_Employee[Employee ID], tbl_Employee[Full Name]) -> Karan Malhotra | C8: 80 | D8: =_xlfn.XLOOKUP(A8, Payroll!A:A, Payroll!C:C) -> 90 | E8: 86 | F8: =IF(AVERAGE(C8,D8,E8)>=85,"Excellent",IF(AVERAGE(C8,D8,E8)>=70,"Good",IF(AVERAGE(C8,D8,E8)>=55,"Average","Poor"))) -> Excellent
A9: =Employee_Database!A9 -> EMP008 | B9: =_xlfn.XLOOKUP(A9, tbl_Employee[Employee ID], tbl_Employee[Full Name]) -> Pooja Iyer | C9: 83 | D9: =_xlfn.XLOOKUP(A9, Payroll!A:A, Payroll!C:C) -> 73.3 | E9: 90 | F9: =IF(AVERAGE(C9,D9,E9)>=85,"Excellent",IF(AVERAGE(C9,D9,E9)>=70,"Good",IF(AVERAGE(C9,D9,E9)>=55,"Average","Poor"))) -> Good
A10: =Employee_Database!A10 -> EMP009 | B10: =_xlfn.XLOOKUP(A10, tbl_Employee[Employee ID], tbl_Employee[Full Name]) -> Rahul Kapoor | C10: 70 | D10: =_xlfn.XLOOKUP(A10, Payroll!A:A, Payroll!C:C) -> 83.3 | E10: 87 | F10: =IF(AVERAGE(C10,D10,E10)>=85,"Excellent",IF(AVERAGE(C10,D10,E10)>=70,"Good",IF(AVERAGE(C10,D10,E10)>=55,"Average","Poor"))) -> Good
A11: =Employee_Database!A11 -> EMP010 | B11: =_xlfn.XLOOKUP(A11, tbl_Employee[Employee ID], tbl_Employee[Full Name]) -> Neha Reddy | C11: 80 | D11: =_xlfn.XLOOKUP(A11, Payroll!A:A, Payroll!C:C) -> 86.7 | E11: 91 | F11: =IF(AVERAGE(C11,D11,E11)>=85,"Excellent",IF(AVERAGE(C11,D11,E11)>=70,"Good",IF(AVERAGE(C11,D11,E11)>=55,"Average","Poor"))) -> Excellent
A12: =Employee_Database!A12 -> EMP011 | B12: =_xlfn.XLOOKUP(A12, tbl_Employee[Employee ID], tbl_Employee[Full Name]) -> Arjun Desai | C12: 65 | D12: =_xlfn.XLOOKUP(A12, Payroll!A:A, Payroll!C:C) -> 81.7 | E12: 91 | F12: =IF(AVERAGE(C12,D12,E12)>=85,"Excellent",IF(AVERAGE(C12,D12,E12)>=70,"Good",IF(AVERAGE(C12,D12,E12)>=55,"Average","Poor"))) -> Good
A13: =Employee_Database!A13 -> EMP012 | B13: =_xlfn.XLOOKUP(A13, tbl_Employee[Employee ID], tbl_Employee[Full Name]) -> Divya Pillai | C13: 75 | D13: =_xlfn.XLOOKUP(A13, Payroll!A:A, Payroll!C:C) -> 86.7 | E13: 57 | F13: =IF(AVERAGE(C13,D13,E13)>=85,"Excellent",IF(AVERAGE(C13,D13,E13)>=70,"Good",IF(AVERAGE(C13,D13,E13)>=55,"Average","Poor"))) -> Good
... A41: =Employee_Database!A41 -> EMP040 | B41: =_xlfn.XLOOKUP(A41, tbl_Employee[Employee ID], tbl_Employee[Full Name]) -> Sunita Bhatia | C41: 70 | D41: =_xlfn.XLOOKUP(A41, Payroll!A:A, Payroll!C:C) -> 83.3 | E41: 83 | F41: =IF(AVERAGE(C41,D41,E41)>=85,"Excellent",IF(AVERAGE(C41,D41,E41)>=70,"Good",IF(AVERAGE(C41,D41,E41)>=55,"Average","Poor"))) -> Good

Sheet Dashboard
